[2023-01-15T01:16:13.939+0000] {taskinstance.py:1165} INFO - Dependencies all met for <TaskInstance: first_dag_v5.2nd_task scheduled__2023-01-14T00:00:00+00:00 [queued]>
[2023-01-15T01:16:13.968+0000] {taskinstance.py:1165} INFO - Dependencies all met for <TaskInstance: first_dag_v5.2nd_task scheduled__2023-01-14T00:00:00+00:00 [queued]>
[2023-01-15T01:16:13.969+0000] {taskinstance.py:1362} INFO - 
--------------------------------------------------------------------------------
[2023-01-15T01:16:13.970+0000] {taskinstance.py:1363} INFO - Starting attempt 1 of 1
[2023-01-15T01:16:13.970+0000] {taskinstance.py:1364} INFO - 
--------------------------------------------------------------------------------
[2023-01-15T01:16:14.015+0000] {taskinstance.py:1383} INFO - Executing <Task(BashOperator): 2nd_task> on 2023-01-14 00:00:00+00:00
[2023-01-15T01:16:14.024+0000] {standard_task_runner.py:54} INFO - Started process 21 to run task
[2023-01-15T01:16:14.031+0000] {standard_task_runner.py:82} INFO - Running: ['airflow', 'tasks', 'run', 'first_dag_v5', '2nd_task', 'scheduled__2023-01-14T00:00:00+00:00', '--job-id', '13', '--raw', '--subdir', 'DAGS_FOLDER/first_dag.py', '--cfg-path', '/tmp/tmpaswizpto']
[2023-01-15T01:16:14.034+0000] {standard_task_runner.py:83} INFO - Job 13: Subtask 2nd_task
[2023-01-15T01:16:14.037+0000] {dagbag.py:525} INFO - Filling up the DagBag from /opt/airflow/dags/repo/Airflow/dags/first_dag.py
[2023-01-15T01:16:14.323+0000] {task_command.py:384} INFO - Running <TaskInstance: first_dag_v5.2nd_task scheduled__2023-01-14T00:00:00+00:00 [running]> on host firstdagv52ndtask-ecb7cb01f3a947c694f3944bc566bd08
[2023-01-15T01:16:17.298+0000] {taskinstance.py:1592} INFO - Exporting the following env vars:
AIRFLOW_CTX_DAG_OWNER=airflow
AIRFLOW_CTX_DAG_ID=first_dag_v5
AIRFLOW_CTX_TASK_ID=2nd_task
AIRFLOW_CTX_EXECUTION_DATE=2023-01-14T00:00:00+00:00
AIRFLOW_CTX_TRY_NUMBER=1
AIRFLOW_CTX_DAG_RUN_ID=scheduled__2023-01-14T00:00:00+00:00
[2023-01-15T01:16:17.301+0000] {subprocess.py:63} INFO - Tmp dir root location: 
 /tmp
[2023-01-15T01:16:17.302+0000] {subprocess.py:75} INFO - Running command: ['/bin/bash', '-c', 'will run after task1']
[2023-01-15T01:16:17.324+0000] {subprocess.py:86} INFO - Output:
[2023-01-15T01:16:17.330+0000] {subprocess.py:93} INFO - /bin/bash: line 1: will: command not found
[2023-01-15T01:16:17.331+0000] {subprocess.py:97} INFO - Command exited with return code 127
[2023-01-15T01:16:17.365+0000] {taskinstance.py:1851} ERROR - Task failed with exception
Traceback (most recent call last):
  File "/home/airflow/.local/lib/python3.7/site-packages/airflow/operators/bash.py", line 197, in execute
    f'Bash command failed. The command returned a non-zero exit code {result.exit_code}.'
airflow.exceptions.AirflowException: Bash command failed. The command returned a non-zero exit code 127.
[2023-01-15T01:16:17.376+0000] {taskinstance.py:1406} INFO - Marking task as FAILED. dag_id=first_dag_v5, task_id=2nd_task, execution_date=20230114T000000, start_date=20230115T011613, end_date=20230115T011617
[2023-01-15T01:16:17.423+0000] {standard_task_runner.py:107} ERROR - Failed to execute job 13 for task 2nd_task (Bash command failed. The command returned a non-zero exit code 127.; 21)
[2023-01-15T01:16:17.501+0000] {local_task_job.py:164} INFO - Task exited with return code 1
[2023-01-15T01:16:17.552+0000] {local_task_job.py:273} INFO - 0 downstream tasks scheduled from follow-on schedule check
